Workbook

Sheet Financial Statement Amazon
A1: Financial Statement for: AMAZON.COM INC
A2: Fiscal Years: 2021 to 2024
B3: 2021 | C3: 2022 | D3: 2023 | E3: 2024
A5: BALANCE SHEET
A6: ASSETS
A7: Cash and Short-Term Investments | B7: 96291 | C7: 70384 | D7: 87277 | E7: 101449
A8: Cash | B8: 36220 | C8: 53888 | D8: 73387 | E8: 78779
A9: Short-Term Investments | B9: 60071 | C9: 16496 | D9: 13890 | E9: 22670
A10: Receivables | B10: 26500 | C10: 34800 | D10: 46900 | E10: 49300
A11: Receivables - Trade | B11: 26500 | C11: 34800 | D11: 43600 | E11: 45900
A12: Income Tax Refund | B12: 0 | C12: 0 | D12: 0 | E12: 0
A13: Current Receivables - Other | B13: 0 | C13: 0 | D13: 3300 | E13: 3400
A14: Inventories - Total | B14: 31758 | C14: 33457 | D14: 32326 | E14: 33216
A15: Inventories - Raw Materials | B15: 0 | C15: 0 | D15: 0 | E15: 0
A16: Inventories - Work in Process | B16: 0 | C16: 0 | D16: 0 | E16: 0
A17: Inventories - Finished Goods | B17: 31758 | C17: 33457 | D17: 32326 | E17: 33216
A18: Inventories - Other | B18: 0 | C18: 0 | D18: 0 | E18: 0
A19: Current Assets - Other | B19: 7031 | C19: 8150 | D19: 5848 | E19: 6902
A20: Prepaid Expense | B20: 0 | C20: 0 | D20: . | E20: .
A21: Other Curr.Asst, Excl.Ppd.Exp. | B21: 7031 | C21: 8150 | D21: 5848 | E21: 6902
A22: Current Assets - Total | B22: 161580 | C22: 146791 | D22: 172351 | E22: 190867
A23: Prop.Plant & Equip.- Total (Net) | B23: 216363 | C23: 252838 | D23: 276690 | E23: 328806
A24: P.P.& E.- Total (Gross) | B24: 294882 | C24: 349853 | D24: 396801 | E24: 470196
A25: Deprec.Depl.& Amort. | B25: 78519 | C25: 97015 | D25: 120111 | E25: 141390
A26: Invest. & Advances - Eq.Meth. | B26: . | C26: . | D26: . | E26: .
A27: Invest. & Advances - Other | B27: 6700 | C27: 4300 | D27: 5900 | E27: 20000
A28: Intangibles | B28: 20478 | C28: 26385 | D28: 30476 | E28: 31676
A29: Assets - Other | B29: 15428 | C29: 32361 | D29: 42437 | E29: 53545
A30: Deferred Charges | B30: 0 | C30: 0 | D30: 0 | E30: 0
A31: Other Asst., Excl.Def.Chg. | B31: 15428 | C31: 32361 | D31: 42437 | E31: 53545
A32: Assets - Total | B32: 420549 | C32: 462675 | D32: 527854 | E32: 624894
A33: LIABILITIES
A34: Debt in Current Liabilities | B34: 17162 | C34: 23120 | D34: 19561 | E34: 17401
A35: Notes Payable | B35: 1043 | C35: 8000 | D35: 147 | E35: 151
A36: Debt - Due in One Year | B36: 16119 | C36: 15120 | D36: 19414 | E36: 17250
A37: Accounts Payable | B37: 78664 | C37: 79600 | D37: 84981 | E37: 94363
A38: Income Taxes Payable | B38: 0 | C38: 0 | D38: 0 | E38: 0
A39: Current Liabilities - Other | B39: 46440 | C39: 52673 | D39: 60375 | E39: 67667
A40: Accrued Expense | B40: . | C40: . | D40: . | E40: .
A41: Other Curr.Liab., Excl.Accr.Exp. | B41: 46440 | C41: 52673 | D41: 60375 | E41: 67667
...

Sheet Financial Statement Walmart
A1: Financial Statement for: WALMART INC
A2: Fiscal Years: 2021 to 2024
B3: 2021 | C3: 2022 | D3: 2023 | E3: 2024
A5: BALANCE SHEET
A6: ASSETS
A7: Cash and Short-Term Investments | B7: 14760 | C7: 8625 | D7: 9867 | E7: 9037
A8: Cash | B8: . | C8: . | D8: . | E8: .
A9: Short-Term Investments | B9: . | C9: . | D9: . | E9: .
A10: Receivables | B10: 8280 | C10: 7933 | D10: 8796 | E10: 9975
A11: Receivables - Trade | B11: 8280 | C11: 7933 | D11: 8796 | E11: 9975
A12: Income Tax Refund | B12: 0 | C12: 0 | D12: 0 | E12: 0
A13: Current Receivables - Other | B13: 0 | C13: 0 | D13: 0 | E13: 0
A14: Inventories - Total | B14: 56511 | C14: 56576 | D14: 54892 | E14: 56435
A15: Inventories - Raw Materials | B15: . | C15: . | D15: . | E15: .
A16: Inventories - Work in Process | B16: . | C16: . | D16: . | E16: .
A17: Inventories - Finished Goods | B17: . | C17: . | D17: . | E17: .
A18: Inventories - Other | B18: . | C18: . | D18: . | E18: .
A19: Current Assets - Other | B19: 1519 | C19: 2521 | D19: 3322 | E19: 4011
A20: Prepaid Expense | B20: . | C20: . | D20: . | E20: .
A21: Other Curr.Asst, Excl.Ppd.Exp. | B21: 1519 | C21: 2521 | D21: 3322 | E21: 4011
A22: Current Assets - Total | B22: 81070 | C22: 75655 | D22: 76877 | E22: 79458
A23: Prop.Plant & Equip.- Total (Net) | B23: 112624 | C23: 119234 | D23: 130338 | E23: 139704
A24: P.P.& E.- Total (Gross) | B24: 207433 | C24: 220844 | D24: 239387 | E24: 251328
A25: Deprec.Depl.& Amort. | B25: 94809 | C25: 101610 | D25: 109049 | E25: 111624
A26: Invest. & Advances - Eq.Meth. | B26: . | C26: . | D26: . | E26: .
A27: Invest. & Advances - Other | B27: 12888 | C27: 11169 | D27: 8449 | E27: 4241
A28: Intangibles | B28: 33814 | C28: 32474 | D28: 32213 | E28: 33292
A29: Assets - Other | B29: 4464 | C29: 4665 | D29: 4522 | E29: 4128
A30: Deferred Charges | B30: . | C30: . | D30: . | E30: .
A31: Other Asst., Excl.Def.Chg. | B31: 4464 | C31: 4665 | D31: 4522 | E31: 4128
A32: Assets - Total | B32: 244860 | C32: 243197 | D32: 252399 | E32: 260823
A33: LIABILITIES
A34: Debt in Current Liabilities | B34: 5207 | C34: 6603 | D34: 6537 | E34: 7965
A35: Notes Payable | B35: 410 | C35: 372 | D35: 878 | E35: 3068
A36: Debt - Due in One Year | B36: 4797 | C36: 6231 | D36: 5659 | E36: 4897
A37: Accounts Payable | B37: 55261 | C37: 53742 | D37: 56812 | E37: 58666
A38: Income Taxes Payable | B38: 851 | C38: 727 | D38: 307 | E38: 608
A39: Current Liabilities - Other | B39: 26060 | C39: 31126 | D39: 28759 | E39: 29345
A40: Accrued Expense | B40: 23480 | C40: 25689 | D40: 26095 | E40: 26590
A41: Other Curr.Liab., Excl.Accr.Exp. | B41: 2580 | C41: 5437 | D41: 2664 | E41: 2755
...

Sheet Key Ratios
A1: Particulars | B1: Amazon | E1: Walmart
B2: 2022 | C2: 2023 | D2: 2024 | E2: 2022 | F2: 2023 | G2: 2024
A3: Return on Equity (ROE)
A4: Net Income/(Loss) | B4: ='Financial Statement Amazon'!C109 -> -2722 | C4: ='Financial Statement Amazon'!D109 -> 30425 | D4: ='Financial Statement Amazon'!E109 -> 59248 | E4: ='Financial Statement Walmart'!C109 -> 11680 | F4: ='Financial Statement Walmart'!D109 -> 15511 | G4: ='Financial Statement Walmart'!E109 -> 19436
A5: Average Equity | B5: =AVERAGE('Financial Statement Amazon'!B69:C69) -> 142144 | C5: =AVERAGE('Financial Statement Amazon'!C69:D69) -> 173959 | D5: =AVERAGE('Financial Statement Amazon'!D69:E69) -> 243922.5 | E5: =AVERAGE('Financial Statement Walmart'!B69:C69) -> 87822.5 | F5: =AVERAGE('Financial Statement Walmart'!C69:D69) -> 87051.5 | G5: =AVERAGE('Financial Statement Walmart'!D69:E69) -> 93885
A6: ROE | B6: =B4/B5 -> -0.019149595 | C6: =C4/C5 -> 0.17489753 | D6: =D4/D5 -> 0.24289682 | E6: =E4/E5 -> 0.13299553 | F6: =F4/F5 -> 0.17818188 | G6: =G4/G5 -> 0.20701923
A8: Return on Asset (ROA)
A9: Net Income/(Loss) | B9: ='Financial Statement Amazon'!C109 -> -2722 | C9: ='Financial Statement Amazon'!D109 -> 30425 | D9: ='Financial Statement Amazon'!E109 -> 59248 | E9: =E4 -> 11680 | F9: =F4 -> 15511 | G9: =G4 -> 19436
A10: Average Total Asset | B10: =AVERAGE('Financial Statement Amazon'!B32:C32) -> 441612 | C10: =AVERAGE('Financial Statement Amazon'!C32:D32) -> 495264.5 | D10: =AVERAGE('Financial Statement Amazon'!D32:E32) -> 576374 | E10: =AVERAGE('Financial Statement Walmart'!B32:C32) -> 244028.5 | F10: =AVERAGE('Financial Statement Walmart'!C32:D32) -> 247798 | G10: =AVERAGE('Financial Statement Walmart'!D32:E32) -> 256611
A11: ROA | B11: =B9/B10 -> -0.0061637818 | C11: =C9/C10 -> 0.061431821 | D11: =D9/D10 -> 0.10279437 | E11: =E9/E10 -> 0.047863262 | F11: =F9/F10 -> 0.06259534 | G11: =G9/G10 -> 0.075741102
A13: Return on net operating assets (RNOA)
A14: Net Operating Profit After Tax | B14: ='Additional Calculation'!B10 -> 12397.34 | C14: ='Additional Calculation'!C10 -> 29925.72 | D14: ='Additional Calculation'!D10 -> 60171.95 | E14: ='Additional Calculation'!E10 -> 15859.16 | F14: ='Additional Calculation'!F10 -> 18556.04 | G14: ='Additional Calculation'!G10 -> 22713.81
A15: Average Net Operating Asset | B15: =AVERAGE('Additional Calculation'!B29:C29) -> 257710.5 | C15: =AVERAGE('Additional Calculation'!C29:D29) -> 312407.5 | D15: =AVERAGE('Additional Calculation'!D29:E29) -> 359217 | E15: =AVERAGE('Additional Calculation'!E29:F29) -> 256293 | F15: =AVERAGE('Additional Calculation'!F29:G29) -> 127140.5 | G15: =AVERAGE('Additional Calculation'!G29:H29) -> 132915.5
A16: RNOA | B16: =B14/B15 -> 0.048105684 | C16: =C14/C15 -> 0.095790658 | D16: =D14/D15 -> 0.16750864 | E16: =E14/E15 -> 0.061879021 | F16: =F14/F15 -> 0.14594909 | G16: =G14/G15 -> 0.1708891
A18: Inventory Turnover Ratio
A19: Cost of Goods Sold(COGS) | B19: ='Financial Statement Amazon'!C74 -> 263907 | C19: ='Financial Statement Amazon'!D74 -> 274514 | D19: ='Financial Statement Amazon'!E74 -> 294221 | E19: ='Financial Statement Walmart'!C74 -> 452776 | F19: ='Financial Statement Walmart'!D74 -> 478289 | G19: ='Financial Statement Walmart'!E74 -> 498780
A20: Average Inventory | B20: =AVERAGE('Financial Statement Amazon'!B14:C14) -> 32607.5 | C20: =AVERAGE('Financial Statement Amazon'!C14:D14) -> 32891.5 | D20: =AVERAGE('Financial Statement Amazon'!D14:E14) -> 32771 | E20: =AVERAGE('Financial Statement Walmart'!B14:C14) -> 56543.5 | F20: =AVERAGE('Financial Statement Walmart'!C14:D14) -> 55734 | G20: =AVERAGE('Financial Statement Walmart'!D14:E14) -> 55663.5
A21: Inventory Turnover Ratio | B21: =B19/B20 -> 8.0934448 | C21: =C19/C20 -> 8.3460469 | D21: =D19/D20 -> 8.9780904 | E21: =E19/E20 -> 8.0075694 | F21: =F19/F20 -> 8.5816378 | G21: =G19/G20 -> 8.9606295
A23: Account Recievable Turnover
A24: Sales | B24: ='Financial Statement Amazon'!C73 -> 513983 | C24: ='Financial Statement Amazon'!D73 -> 574785 | D24: ='Financial Statement Amazon'!E73 -> 637959 | E24: ='Financial Statement Walmart'!C73 -> 608481 | F24: ='Financial Statement Walmart'!D73 -> 645737 | G24: ='Financial Statement Walmart'!E73 -> 680985
A25: Average Account Recievable | B25: =AVERAGE('Financial Statement Amazon'!B10:C10) -> 30650 | C25: =AVERAGE('Financial Statement Amazon'!C10:D10) -> 40850 | D25: =AVERAGE('Financial Statement Amazon'!D10:E10) -> 48100 | E25: =AVERAGE('Financial Statement Walmart'!B10:C10) -> 8106.5 | F25: =AVERAGE('Financial Statement Walmart'!C10:D10) -> 8364.5 | G25: =AVERAGE('Financial Statement Walmart'!D10:E10) -> 9385.5
A26: ARTO | B26: =B24/B25 -> 16.769429 | C26: =C24/C25 -> 14.070624 | D26: =D24/D25 -> 13.263181 | E26: =E24/E25 -> 75.060877 | F26: =F24/F25 -> 77.199713 | G26: =G24/G25 -> 72.557136
A28: Account Payable Turnover
A29: Cost of Goods Sold | B29: ='Financial Statement Amazon'!C74 -> 263907 | C29: ='Financial Statement Amazon'!D74 -> 274514 | D29: ='Financial Statement Amazon'!E74 -> 294221 | E29: ='Financial Statement Walmart'!C74 -> 452776 | F29: ='Financial Statement Walmart'!D74 -> 478289 | G29: ='Financial Statement Walmart'!E74 -> 498780
A30: Average Account Payable | B30: =AVERAGE('Financial Statement Amazon'!B37:C37) -> 79132 | C30: =AVERAGE('Financial Statement Amazon'!C37:D37) -> 82290.5 | D30: =AVERAGE('Financial Statement Amazon'!D37:E37) -> 89672 | E30: =AVERAGE('Financial Statement Walmart'!B37:C37) -> 54501.5 | F30: =AVERAGE('Financial Statement Walmart'!C37:D37) -> 55277 | G30: =AVERAGE('Financial Statement Walmart'!D37:E37) -> 57739
A31: APTO | B31: =B29/B30 -> 3.3350225 | C31: =C29/C30 -> 3.3359136 | D31: =D29/D30 -> 3.2810799 | E31: =E29/E30 -> 8.3075879 | F31: =F29/F30 -> 8.6525861 | G31: =G29/G30 -> 8.6385286
A33: PPE Turnover
A34: Sales | B34: =B24 -> 513983 | C34: =C24 -> 574785 | D34: =D24 -> 637959 | E34: =E24 -> 608481 | F34: =F24 -> 645737 | G34: =G24 -> 680985
A35: Average PPE Asset | B35: =AVERAGE('Financial Statement Amazon'!B23:C23) -> 234600.5 | C35: =AVERAGE('Financial Statement Amazon'!C23:D23) -> 264764 | D35: =AVERAGE('Financial Statement Amazon'!D23:E23) -> 302748 | E35: =AVERAGE('Financial Statement Walmart'!B23:C23) -> 115929 | F35: =AVERAGE('Financial Statement Walmart'!C23:D23) -> 124786 | G35: =AVERAGE('Financial Statement Walmart'!D23:E23) -> 135021
A36: PPETO | B36: =B34/B35 -> 2.1908862 | C36: =C34/C35 -> 2.1709334 | D36: =D34/D35 -> 2.1072278 | E36: =E34/E35 -> 5.2487385 | F36: =F34/F35 -> 5.1747552 | G36: =G34/G35 -> 5.0435488
A38: Times Interest Earned
A39: EBIT | B39: ='Financial Statement Amazon'!C81 -> 12907 | C39: ='Financial Statement Amazon'!D81 -> 36913 | D39: ='Financial Statement Amazon'!E81 -> 69438 | E39: ='Financial Statement Walmart'!C81 -> 21794 | F39: ='Financial Statement Walmart'!D81 -> 24717 | G39: ='Financial Statement Walmart'!E81 -> 29504
A40: Interest Expenses | B40: ='Financial Statement Amazon'!C82 -> 2367 | C40: ='Financial Statement Amazon'!D82 -> 3182 | D40: ='Financial Statement Amazon'!E82 -> 2406 | E40: ='Financial Statement Walmart'!C82 -> 2128 | F40: ='Financial Statement Walmart'!D82 -> 2683 | G40: ='Financial Statement Walmart'!E82 -> 2728
A41: TIE | B41: =B39/B40 -> 5.452894 | C41: =C39/C40 -> 11.600566 | D41: =D39/D40 -> 28.860349 | E41: =E39/E40 -> 10.241541 | F41: =F39/F40 -> 9.2124488 | G41: =G39/G40 -> 10.815249
A43: EBITDA Coverage Ratio
A44: EBIT+Depreciation+ Amortization | B44: =B39+'Financial Statement Amazon'!C77 -> 38435 | C44: =C39+'Financial Statement Amazon'!D77 -> 67844 | D44: =D39+'Financial Statement Amazon'!E77 -> 101423 | E44: =E39+'Financial Statement Walmart'!C77 -> 32739 | F44: =F39+'Financial Statement Walmart'!D77 -> 36570 | G44: =G39+'Financial Statement Walmart'!E77 -> 42477
A45: Interest Expenses | B45: =B40 -> 2367 | C45: =C40 -> 3182 | D45: =D40 -> 2406 | E45: =E40 -> 2128 | F45: =F40 -> 2683 | G45: =G40 -> 2728
A46: EBITDA Coverage Ratio | B46: =B44/B45 -> 16.237854 | C46: =C44/C45 -> 21.321182 | D46: =D44/D45 -> 42.154198 | E46: =E44/E45 -> 15.384868 | F46: =F44/F45 -> 13.630265 | G46: =G44/G45 -> 15.570748
A48: Operating Cashflow To Debt
A49: Cash From Operation | B49: ='Financial Statement Amazon'!C125 -> 46752 | C49: ='Financial Statement Amazon'!D125 -> 84946 | D49: ='Financial Statement Amazon'!E125 -> 115877 | E49: ='Financial Statement Walmart'!C125 -> 28841 | F49: ='Financial Statement Walmart'!D125 -> 35726 | G49: ='Financial Statement Walmart'!E125 -> 36443
...

Sheet Additional Calculation
A1: Particulars | B1: Amazon | E1: Walmart
B2: 2022 | C2: 2023 | D2: 2024 | E2: 2022 | F2: 2023 | G2: 2024
A3: ='Financial Statement Amazon'!A81 -> Operating Income After Depreciation | B3: ='Financial Statement Amazon'!C81 -> 12907 | C3: ='Financial Statement Amazon'!D81 -> 36913 | D3: ='Financial Statement Amazon'!E81 -> 69438 | E3: ='Financial Statement Walmart'!C81 -> 21794 | F3: ='Financial Statement Walmart'!D81 -> 24717 | G3: ='Financial Statement Walmart'!E81 -> 29504
A4: EBIT | B4: =B3 -> 12907 | C4: =C3 -> 36913 | D4: =D3 -> 69438 | E4: =E3 -> 21794 | F4: =F3 -> 24717 | G4: =G3 -> 29504
A5: (less) Tax on Operating Profit
A6: Tax Expense | B6: ='Financial Statement Amazon'!C90 -> -3217 | C6: ='Financial Statement Amazon'!D90 -> 7120 | D6: ='Financial Statement Amazon'!E90 -> 9265 | E6: ='Financial Statement Walmart'!C90 -> 5724 | F6: ='Financial Statement Walmart'!D90 -> 5578 | G6: ='Financial Statement Walmart'!E90 -> 6152
A7: Pretax non operating expense | B7: ='Financial Statement Amazon'!C82-'Financial Statement Amazon'!C83 -> 17746 | C7: ='Financial Statement Amazon'!D82-'Financial Statement Amazon'!D83 -> -632 | D7: ='Financial Statement Amazon'!E82-'Financial Statement Amazon'!E83 -> 5 | E7: ='Financial Statement Walmart'!C82-'Financial Statement Walmart'!C83 -> 1004 | F7: ='Financial Statement Walmart'!D82-'Financial Statement Walmart'!D83 -> 2776 | G7: ='Financial Statement Walmart'!E82-'Financial Statement Walmart'!E83 -> 3039
A8: Statutary Tax Rate | B8: 0.21 | C8: 0.21 | D8: 0.21 | E8: 0.21 | F8: 0.21 | G8: 0.21
B9: =B6+(B7*B8) -> 509.66 | C9: =C6+(C7*C8) -> 6987.28 | D9: =D6+(D7*D8) -> 9266.05 | E9: =E6+(E7*E8) -> 5934.84 | F9: =F6+(F7*F8) -> 6160.96 | G9: =G6+(G7*G8) -> 6790.19
A10: NOPAT | B10: =B4-B9 -> 12397.34 | C10: =C4-C9 -> 29925.72 | D10: =D4-D9 -> 60171.95 | E10: =E4-E9 -> 15859.16 | F10: =F4-F9 -> 18556.04 | G10: =G4-G9 -> 22713.81
A12: Particulars | B12: Amazon | F12: Walmart
A13: Operating Asset | B13: 2021 | C13: 2022 | D13: 2023 | E13: 2024 | F13: 2021 | G13: 2022 | H13: 2023 | I13: 2024
A14: Accounts Receivable | B14: ='Financial Statement Amazon'!B10 -> 26500 | C14: ='Financial Statement Amazon'!C10 -> 34800 | D14: ='Financial Statement Amazon'!D10 -> 46900 | E14: ='Financial Statement Amazon'!E10 -> 49300 | F14: ='Financial Statement Walmart'!B10 -> 8280 | G14: ='Financial Statement Walmart'!C10 -> 7933 | H14: ='Financial Statement Walmart'!D10 -> 8796 | I14: ='Financial Statement Walmart'!E10 -> 9975
A15: Inventories | B15: ='Financial Statement Amazon'!B14 -> 31758 | C15: ='Financial Statement Amazon'!C14 -> 33457 | D15: ='Financial Statement Amazon'!D14 -> 32326 | E15: ='Financial Statement Amazon'!E14 -> 33216 | F15: ='Financial Statement Walmart'!B14 -> 56511 | G15: ='Financial Statement Walmart'!C14 -> 56576 | H15: ='Financial Statement Walmart'!D14 -> 54892 | I15: ='Financial Statement Walmart'!E14 -> 56435
A16: Other Current Assets | B16: ='Financial Statement Amazon'!B19 -> 7031 | C16: ='Financial Statement Amazon'!C19 -> 8150 | D16: ='Financial Statement Amazon'!D19 -> 5848 | E16: ='Financial Statement Amazon'!E19 -> 6902 | F16: ='Financial Statement Walmart'!B19 -> 1519 | G16: ='Financial Statement Walmart'!C19 -> 2521 | H16: ='Financial Statement Walmart'!D19 -> 3322 | I16: ='Financial Statement Walmart'!E19 -> 4011
A17: PPE | B17: ='Financial Statement Amazon'!B23 -> 216363 | C17: ='Financial Statement Amazon'!C23 -> 252838 | D17: ='Financial Statement Amazon'!D23 -> 276690 | E17: ='Financial Statement Amazon'!E23 -> 328806 | F17: ='Financial Statement Walmart'!B23 -> 112624 | G17: ='Financial Statement Walmart'!C23 -> 119234 | H17: ='Financial Statement Walmart'!D23 -> 130338 | I17: ='Financial Statement Walmart'!E23 -> 139704
A18: Goodwill and Intangible assets. | B18: ='Financial Statement Amazon'!B28 -> 20478 | C18: ='Financial Statement Amazon'!C28 -> 26385 | D18: ='Financial Statement Amazon'!D28 -> 30476 | E18: ='Financial Statement Amazon'!E28 -> 31676 | F18: ='Financial Statement Walmart'!B28 -> 33814 | G18: ='Financial Statement Walmart'!C28 -> 32474 | H18: ='Financial Statement Walmart'!D28 -> 32213 | I18: ='Financial Statement Walmart'!E28 -> 33292
A19: Other Long-Term assets. | B19: ='Financial Statement Amazon'!B29 -> 15428 | C19: ='Financial Statement Amazon'!C29 -> 32361 | D19: ='Financial Statement Amazon'!D29 -> 42437 | E19: ='Financial Statement Amazon'!E29 -> 53545 | F19: ='Financial Statement Walmart'!B29 -> 4464 | G19: ='Financial Statement Walmart'!C29 -> 4665 | H19: ='Financial Statement Walmart'!D29 -> 4522 | I19: ='Financial Statement Walmart'!E29 -> 4128
A20: Total Operating Assets (A) | B20: =SUM(B14:B19) -> 317558 | C20: =SUM(C14:C19) -> 387991 | D20: =SUM(D14:D19) -> 434677 | E20: =SUM(E14:E19) -> 503445 | F20: =SUM(F14:F19) -> 217212 | G20: =SUM(G14:G19) -> 223403 | H20: =SUM(H14:H19) -> 234083 | I20: =SUM(I14:I19) -> 247545
A22: Operating Liabilities
A23: Accounts Payable | B23: ='Financial Statement Amazon'!B37 -> 78664 | C23: ='Financial Statement Amazon'!C37 -> 79600 | D23: ='Financial Statement Amazon'!D37 -> 84981 | E23: ='Financial Statement Amazon'!E37 -> 94363 | F23: ='Financial Statement Walmart'!B37 -> 55261 | G23: ='Financial Statement Walmart'!C37 -> 53742 | H23: ='Financial Statement Walmart'!D37 -> 56812 | I23: ='Financial Statement Walmart'!E37 -> 58666
A24: Accrued Liabilities | B24: 0 | C24: 0 | D24: 0 | E24: 0 | F24: ='Financial Statement Walmart'!B40 -> 23480 | G24: ='Financial Statement Walmart'!C40 -> 25689 | H24: ='Financial Statement Walmart'!D40 -> 26095 | I24: ='Financial Statement Walmart'!E40 -> 26590
A25: Deferred Tax Liabilities | B25: 0 | C25: 0 | D25: 0 | E25: 0 | F25: ='Financial Statement Walmart'!B54 -> 6917 | G25: ='Financial Statement Walmart'!C54 -> 7269 | H25: ='Financial Statement Walmart'!D54 -> 7248 | I25: ='Financial Statement Walmart'!E54 -> 7019
A26: Other Long term Liabilities | B26: ='Financial Statement Amazon'!B52 -> 17443 | C26: ='Financial Statement Amazon'!C52 -> 14421 | D26: ='Financial Statement Amazon'!D52 -> 18851 | E26: ='Financial Statement Amazon'!E52 -> 21493 | F26: ='Financial Statement Walmart'!B52 -> 6557 | G26: ='Financial Statement Walmart'!C52 -> 7419 | H26: ='Financial Statement Walmart'!D52 -> 7381 | I26: ='Financial Statement Walmart'!E52 -> 7379
A27: Total Operating Liabilities (B) | B27: =SUM(B23:B26) -> 96107 | C27: =SUM(C23:C26) -> 94021 | D27: =SUM(D23:D26) -> 103832 | E27: =SUM(E23:E26) -> 115856 | F27: =SUM(F23:F26) -> 92215 | G27: =SUM(G23:G26) -> 94119 | H27: =SUM(H23:H26) -> 97536 | I27: =SUM(I23:I26) -> 99654
A29: Net Operating Assets (A-B) | B29: =B20-B27 -> 221451 | C29: =C20-C27 -> 293970 | D29: =D20-D27 -> 330845 | E29: =E20-E27 -> 387589 | F29: =F20-F27 -> 124997 | G29: =G20-G27 -> 129284 | H29: =H20-H27 -> 136547 | I29: =I20-I27 -> 147891
B31: Amazon | F31: Walmart
B32: 2021 | C32: 2022 | D32: 2023 | E32: 2024 | F32: 2021 | G32: 2022 | H32: 2023 | I32: 2024
A33: short term Debt
A34: Debt in Current Liabilities | B34: ='Financial Statement Amazon'!B34 -> 17162 | C34: ='Financial Statement Amazon'!C34 -> 23120 | D34: ='Financial Statement Amazon'!D34 -> 19561 | E34: ='Financial Statement Amazon'!E34 -> 17401 | F34: ='Financial Statement Walmart'!B34 -> 5207 | G34: ='Financial Statement Walmart'!C34 -> 6603 | H34: ='Financial Statement Walmart'!D34 -> 6537 | I34: ='Financial Statement Walmart'!E34 -> 7965
A35: Long term Debt
A36: Debt - Notes | B36: ='Financial Statement Amazon'!B48 -> 49750 | C36: ='Financial Statement Amazon'!C48 -> 69500 | D36: ='Financial Statement Amazon'!D48 -> 66500 | E36: ='Financial Statement Amazon'!E48 -> 58000 | F36: ='Financial Statement Walmart'!B48 -> 34864 | G36: ='Financial Statement Walmart'!C48 -> 34649 | H36: ='Financial Statement Walmart'!D48 -> 36132 | I36: ='Financial Statement Walmart'!E48 -> 33401
A37: Total Debt | B37: =B34+B36 -> 66912 | C37: =C34+C36 -> 92620 | D37: =D34+D36 -> 86061 | E37: =E34+E36 -> 75401 | F37: =F34+F36 -> 40071 | G37: =G34+G36 -> 41252 | H37: =H34+H36 -> 42669 | I37: =I34+I36 -> 41366
A41: Non Operating Asset | B41: ='Financial Statement Amazon'!E7 -> 101449
A42: Non Operating Liablities | B42: ='Financial Statement Amazon'!E34+'Financial Statement Amazon'!E43 -> 155401
A43: NNO | B43: =B42-B41 -> 53952

Sheet Profitability Ratio Analysis
A2: Productivity Ratios Analysis
D3: Amazon | H3: Walmart
A4: Particular | E4: 2022 | F4: 2023 | G4: 2024 | H4: 2022 | I4: 2023 | J4: 2024
A6: Traditional Dupont Disaggregation
A7: Return On Earning | E7: ='Key Ratios'!B6 -> -0.019149595 | F7: ='Key Ratios'!C6 -> 0.17489753 | G7: ='Key Ratios'!D6 -> 0.24289682 | H7: ='Key Ratios'!E6 -> 0.13299553 | I7: ='Key Ratios'!F6 -> 0.17818188 | J7: ='Key Ratios'!G6 -> 0.20701923
A9: Return on Asset | E9: ='Key Ratios'!B11 -> -0.0061637818 | F9: ='Key Ratios'!C11 -> 0.061431821 | G9: ='Key Ratios'!D11 -> 0.10279437 | H9: ='Key Ratios'!E11 -> 0.047863262 | I9: ='Key Ratios'!F11 -> 0.06259534 | J9: ='Key Ratios'!G11 -> 0.075741102
A11: Financial leverage | E11: ='Key Ratios'!B82 -> 3.1067931 | F11: ='Key Ratios'!C82 -> 2.8470186 | G11: ='Key Ratios'!D82 -> 2.362939 | H11: ='Key Ratios'!E82 -> 2.7786558 | I11: ='Key Ratios'!F82 -> 2.8465678 | J11: ='Key Ratios'!G82 -> 2.7332481
A13: RNOA Disaggregation by NOPM And NOAT
A14: NOPM | E14: ='Key Ratios'!B87 -> 0.024120136 | F14: ='Key Ratios'!C87 -> 0.052064198 | G14: ='Key Ratios'!D87 -> 0.094319463 | H14: ='Key Ratios'!E87 -> 0.026063525 | I14: ='Key Ratios'!F87 -> 0.028736219 | J14: ='Key Ratios'!G87 -> 0.033354347
A16: NOAT | E16: ='Key Ratios'!B92 -> 1.9944201 | F16: ='Key Ratios'!C92 -> 1.8398566 | G16: ='Key Ratios'!D92 -> 1.7759711 | H16: ='Key Ratios'!E92 -> 2.3741616 | I16: ='Key Ratios'!F92 -> 5.0789245 | J16: ='Key Ratios'!G92 -> 5.1234431
A18: RNOA | E18: ='Key Ratios'!B16 -> 0.048105684 | F18: ='Key Ratios'!C16 -> 0.095790658 | G18: ='Key Ratios'!D16 -> 0.16750864 | H18: ='Key Ratios'!E16 -> 0.061879021 | I18: ='Key Ratios'!F16 -> 0.14594909 | J18: ='Key Ratios'!G16 -> 0.1708891
A20: Operating Efficiency
A22: Gross Profit Margin | E22: ='Key Ratios'!B97 -> 0.48654527 | F22: ='Key Ratios'!C97 -> 0.52240577 | G22: ='Key Ratios'!D97 -> 0.53880892 | H22: ='Key Ratios'!E97 -> 0.25589131 | I22: ='Key Ratios'!F97 -> 0.259313 | J22: ='Key Ratios'!G97 -> 0.26756096
A24: Operating Expenses Margin | E24: ='Key Ratios'!B102 -> 0.025111725 | F24: ='Key Ratios'!C102 -> 0.064220535 | G24: ='Key Ratios'!D102 -> 0.10884399 | H24: ='Key Ratios'!E102 -> 0.035817059 | I24: ='Key Ratios'!F102 -> 0.038277193 | J24: ='Key Ratios'!G102 -> 0.043325477
A26: Profit Margin | E26: ='Key Ratios'!B107 -> -0.005295895 | F26: ='Key Ratios'!C107 -> 0.052932836 | G26: ='Key Ratios'!D107 -> 0.092871172 | H26: ='Key Ratios'!E107 -> 0.019195341 | I26: ='Key Ratios'!F107 -> 0.024020615 | J26: ='Key Ratios'!G107 -> 0.02854101

Sheet Productivity Ratio Analysis
A1: Cash Conversion Cycle for Amazon
A3: Ratio | B3: Formulae | C3: 2022 | D3: =C3+1 -> 2023 | E3: =D3+1 -> 2024
A5: Days Sales outstanding | B5: 360*(Average Account Receivable/Sales) | C5: =360*('Key Ratios'!B25/'Key Ratios'!B24) -> 21.467636 | D5: =360*('Key Ratios'!C25/'Key Ratios'!C24) -> 25.585219 | E5: =360*('Key Ratios'!D25/'Key Ratios'!D24) -> 27.14281
A6: Days Inventories Outstanding | B6: 360*(Average Inventory/Sales) | C6: =360*('Key Ratios'!B20/'Key Ratios'!B24) -> 22.838693 | D6: =360*('Key Ratios'!C20/'Key Ratios'!C24) -> 20.600642 | E6: =360*('Key Ratios'!D20/'Key Ratios'!D24) -> 18.492662
A7: Days Payable Outstanding | B7: 360*(Average Account Payable/Sales) | C7: =360*('Key Ratios'!B30/'Key Ratios'!B24) -> 55.425024 | D7: =360*('Key Ratios'!C30/'Key Ratios'!C24) -> 51.54028 | E7: =360*('Key Ratios'!D30/'Key Ratios'!D24) -> 50.601873
A9: Cash Conversion Cycle | C9: =SUM(C5:C7) -> 99.731353 | D9: =SUM(D5:D7) -> 97.726141 | E9: =SUM(E5:E7) -> 96.237344
A12: Cash Conversion Cycle for Walmart
A14: Ratio | B14: Formulae | C14: 2022 | D14: =C14+1 -> 2023 | E14: =D14+1 -> 2024
A16: Days Sales outstanding | B16: 360*(Average Account Receivable/Sales) | C16: =360*('[1]Key Ratios'!H23/'[1]Key Ratios'!H22) -> 54.186486 | D16: =360*('[1]Key Ratios'!I23/'[1]Key Ratios'!I22) -> 55.481712 | E16: =360*('[1]Key Ratios'!J23/'[1]Key Ratios'!J22) -> 52.248376
A17: Days Inventories Outstanding | B17: 360*(Average Inventory/Sales) | C17: 0 | D17: 0 | E17: 0
A18: Days Payable Outstanding | B18: 360*(Average Account Payable/Sales) | C18: =360*('[1]Key Ratios'!H29/'[1]Key Ratios'!H22) -> 13.491892 | D18: =360*('[1]Key Ratios'!I29/'[1]Key Ratios'!I22) -> 12.62252 | E18: =360*('[1]Key Ratios'!J29/'[1]Key Ratios'!J22) -> 11.266376
A20: Cash Conversion Cycle | C20: =SUM(C16:C18) -> 67.678378 | D20: =SUM(D16:D18) -> 68.104231 | E20: =SUM(E16:E18) -> 63.514751

Sheet Liquidy Solvency Ratio
A1: Credit Rating for Amazon -Z -Score
A2: Particular | C2: Ratio | D2: weight | E2: Total
A4: Working Capital | B4: ='Key Ratios'!D60-'Key Ratios'!D61 -> 11436
A5: Total Asset | B5: ='Financial Statement Amazon'!E32 -> 624894 | C5: =B4/B5 -> 0.018300704 | D5: 1.2 | E5: =C5*D5 -> 0.021960845
A7: Retained Earnings | B7: ='Financial Statement Amazon'!E65 -> 172832
A8: Total Asset | B8: =B5 -> 624894 | C8: =B7/B8 -> 0.27657811 | D8: 1.4 | E8: =C8*D8 -> 0.38720935
A10: Earning Before Income and Tax | B10: ='Financial Statement Amazon'!E81 -> 69438
A11: Total Asset | B11: =B8 -> 624894 | C11: =B10/B11 -> 0.11111965 | D11: 3.3 | E11: =C11*D11 -> 0.36669483
A13: Market Value of Equity | B13: 2390000
A14: Total Liabilities | B14: ='Key Ratios'!D70 -> 338924 | C14: =B13/B14 -> 7.0517284 | D14: 0.6 | E14: =C14*D14 -> 4.231037
A16: Sales | B16: ='Financial Statement Amazon'!E73 -> 637959
A17: Total Asset | B17: =B11 -> 624894 | C17: =B16/B17 -> 1.0209075 | D17: 0.99 | E17: =C17*D17 -> 1.0106985
E19: =SUM(E5,E8,E11,E14,E17) -> 6.0176005

Sheet Valuation_DCF
A1: Valuation As per Discounted Cashflow Method(DCF)
H2: Sales growth rate = 2.5%
A3: Cost of Capital (WACC) | B3: 0.098 | D3: Terminal Growth Rate | F3: 0.03
B5: 2024 | C5: 2025 | D5: 2026 | E5: 2027 | F5: Terminal Growth
A7: Sales | B7: ='Financial Statement Amazon'!E73 -> 637959 | C7: =B7*(1+2.5%) -> 653907.97 | D7: =C7*(1+2.5%) -> 670255.67 | E7: =D7*(1+2.5%) -> 687012.07 | F7: =E7*(1+2.5%) -> 704187.37
A8: Net-Operating Profit After Tax | B8: ='Additional Calculation'!D10 -> 60171.95 | C8: 54379 | D8: 59863 | E8: 63458 | F8: 65362
A9: Net-Operating Asset | B9: ='Additional Calculation'!E29 -> 387589 | C9: =B9*109% -> 422472.01 | D9: =C9*102% -> 430921.45 | E9: =D9*102% -> 439539.88 | F9: =E9*102% -> 448330.68
A12: Increase in NOA | C12: =C9-B9 -> 34883.01 | D12: =D9-C9 -> 8449.4402 | E12: =E9-D9 -> 8618.429 | F12: =F9-E9 -> 8790.7976
A13: Free Cashflow | C13: =C8-C12 -> 19495.99 | D13: =D8-D12 -> 51413.56 | E13: =E8-E12 -> 54839.571 | F13: =F8-F12 -> 56571.202 | G13: =F13*(1+3%)/((9.8%-3%)) -> 856887.33
A14: Present Value of Horizon Freecashflow | C14: =C13/(1+$B$3)^1 -> 17755.911 | D14: =D13/(1+$B$3)^2 -> 42645.479 | E14: =E13/(1+$B$3)^3 -> 41427.338
A16: Cum.Present Value Of Horizon Free Cashflow | B16: =SUM(C14:E14) -> 101828.73
A17: Present Value Of Terminal Free cash flow | B17: =G13/(1+9.8%)^3 -> 647316.54
A18: Total Firm Value | B18: =B16+B17 -> 749145.26
A19: Net non-operating Obligation | B19: ='Additional Calculation'!B43 -> 53952
A20: Firm Equity Value | B20: =B18-B19 -> 695193.26
A21: Share Outstanding | B21: 10900
A22: Stock Price Per Share | B22: =B20/B21 -> 63.779198
